[2024-03-29T16:24:03.679-0300] {taskinstance.py:1979} INFO - Dependencies all met for dep_context=non-requeueable deps ti=<TaskInstance: exec-web-scraping.data_prep_gold scheduled__2024-03-29T19:00:00+00:00 [queued]>
[2024-03-29T16:24:03.688-0300] {taskinstance.py:1979} INFO - Dependencies all met for dep_context=requeueable deps ti=<TaskInstance: exec-web-scraping.data_prep_gold scheduled__2024-03-29T19:00:00+00:00 [queued]>
[2024-03-29T16:24:03.689-0300] {taskinstance.py:2193} INFO - Starting attempt 1 of 6
[2024-03-29T16:24:03.702-0300] {taskinstance.py:2217} INFO - Executing <Task(BashOperator): data_prep_gold> on 2024-03-29 19:00:00+00:00
[2024-03-29T16:24:03.704-0300] {standard_task_runner.py:60} INFO - Started process 28611 to run task
[2024-03-29T16:24:03.707-0300] {standard_task_runner.py:87} INFO - Running: ['airflow', 'tasks', 'run', 'exec-web-scraping', 'data_prep_gold', 'scheduled__2024-03-29T19:00:00+00:00', '--job-id', '78', '--raw', '--subdir', 'DAGS_FOLDER/dag_web_scrapping_load_to_minio.py', '--cfg-path', '/tmp/tmp3qs_m2d1']
[2024-03-29T16:24:03.708-0300] {standard_task_runner.py:88} INFO - Job 78: Subtask data_prep_gold
[2024-03-29T16:24:03.783-0300] {task_command.py:423} INFO - Running <TaskInstance: exec-web-scraping.data_prep_gold scheduled__2024-03-29T19:00:00+00:00 [running]> on host DESKTOP-RPMMOLA.
[2024-03-29T16:24:03.908-0300] {taskinstance.py:2513} INFO - Exporting env vars: AIRFLOW_CTX_DAG_OWNER='thiago' AIRFLOW_CTX_DAG_ID='exec-web-scraping' AIRFLOW_CTX_TASK_ID='data_prep_gold' AIRFLOW_CTX_EXECUTION_DATE='2024-03-29T19:00:00+00:00' AIRFLOW_CTX_TRY_NUMBER='1' AIRFLOW_CTX_DAG_RUN_ID='scheduled__2024-03-29T19:00:00+00:00'
[2024-03-29T16:24:03.910-0300] {subprocess.py:63} INFO - Tmp dir root location: /tmp
[2024-03-29T16:24:03.911-0300] {subprocess.py:75} INFO - Running command: ['/usr/bin/bash', '-c', 'python3 /home/thiago/tcc_ufrj/scripts_finalizados/4_data_prep_gold.py']
[2024-03-29T16:24:03.917-0300] {subprocess.py:86} INFO - Output:
[2024-03-29T16:24:05.391-0300] {subprocess.py:93} INFO - Traceback (most recent call last):
[2024-03-29T16:24:05.392-0300] {subprocess.py:93} INFO -   File "/home/thiago/tcc_ufrj/venv/lib/python3.10/site-packages/geopy/geocoders/base.py", line 368, in _call_geocoder
[2024-03-29T16:24:05.393-0300] {subprocess.py:93} INFO -     result = self.adapter.get_json(url, timeout=timeout, headers=req_headers)
[2024-03-29T16:24:05.393-0300] {subprocess.py:93} INFO -   File "/home/thiago/tcc_ufrj/venv/lib/python3.10/site-packages/geopy/adapters.py", line 472, in get_json
[2024-03-29T16:24:05.394-0300] {subprocess.py:93} INFO -     resp = self._request(url, timeout=timeout, headers=headers)
[2024-03-29T16:24:05.394-0300] {subprocess.py:93} INFO -   File "/home/thiago/tcc_ufrj/venv/lib/python3.10/site-packages/geopy/adapters.py", line 500, in _request
[2024-03-29T16:24:05.394-0300] {subprocess.py:93} INFO -     raise AdapterHTTPError(
[2024-03-29T16:24:05.395-0300] {subprocess.py:93} INFO - geopy.adapters.AdapterHTTPError: Non-successful status code 403
[2024-03-29T16:24:05.395-0300] {subprocess.py:93} INFO - 
[2024-03-29T16:24:05.395-0300] {subprocess.py:93} INFO - The above exception was the direct cause of the following exception:
[2024-03-29T16:24:05.396-0300] {subprocess.py:93} INFO - 
[2024-03-29T16:24:05.396-0300] {subprocess.py:93} INFO - Traceback (most recent call last):
[2024-03-29T16:24:05.396-0300] {subprocess.py:93} INFO -   File "/home/thiago/tcc_ufrj/scripts_finalizados/4_data_prep_gold.py", line 57, in <module>
[2024-03-29T16:24:05.396-0300] {subprocess.py:93} INFO -     location = geolocator.reverse(last_location_str)
[2024-03-29T16:24:05.397-0300] {subprocess.py:93} INFO -   File "/home/thiago/tcc_ufrj/venv/lib/python3.10/site-packages/geopy/geocoders/nominatim.py", line 372, in reverse
[2024-03-29T16:24:05.397-0300] {subprocess.py:93} INFO -     return self._call_geocoder(url, callback, timeout=timeout)
[2024-03-29T16:24:05.397-0300] {subprocess.py:93} INFO -   File "/home/thiago/tcc_ufrj/venv/lib/python3.10/site-packages/geopy/geocoders/base.py", line 388, in _call_geocoder
[2024-03-29T16:24:05.397-0300] {subprocess.py:93} INFO -     res = self._adapter_error_handler(error)
[2024-03-29T16:24:05.398-0300] {subprocess.py:93} INFO -   File "/home/thiago/tcc_ufrj/venv/lib/python3.10/site-packages/geopy/geocoders/base.py", line 411, in _adapter_error_handler
[2024-03-29T16:24:05.398-0300] {subprocess.py:93} INFO -     raise exc_cls(str(error)) from error
[2024-03-29T16:24:05.398-0300] {subprocess.py:93} INFO - geopy.exc.GeocoderInsufficientPrivileges: Non-successful status code 403
[2024-03-29T16:24:05.534-0300] {subprocess.py:97} INFO - Command exited with return code 1
[2024-03-29T16:24:05.554-0300] {taskinstance.py:2731} ERROR - Task failed with exception
Traceback (most recent call last):
  File "/home/thiago/tcc_ufrj/venv/lib/python3.10/site-packages/airflow/models/taskinstance.py", line 444, in _execute_task
    result = _execute_callable(context=context, **execute_callable_kwargs)
  File "/home/thiago/tcc_ufrj/venv/lib/python3.10/site-packages/airflow/models/taskinstance.py", line 414, in _execute_callable
    return execute_callable(context=context, **execute_callable_kwargs)
  File "/home/thiago/tcc_ufrj/venv/lib/python3.10/site-packages/airflow/operators/bash.py", line 212, in execute
    raise AirflowException(
airflow.exceptions.AirflowException: Bash command failed. The command returned a non-zero exit code 1.
[2024-03-29T16:24:05.557-0300] {taskinstance.py:1149} INFO - Marking task as UP_FOR_RETRY. dag_id=exec-web-scraping, task_id=data_prep_gold, execution_date=20240329T190000, start_date=20240329T192403, end_date=20240329T192405
[2024-03-29T16:24:05.570-0300] {standard_task_runner.py:107} ERROR - Failed to execute job 78 for task data_prep_gold (Bash command failed. The command returned a non-zero exit code 1.; 28611)
[2024-03-29T16:24:05.605-0300] {local_task_job_runner.py:234} INFO - Task exited with return code 1
[2024-03-29T16:24:05.638-0300] {taskinstance.py:3312} INFO - 0 downstream tasks scheduled from follow-on schedule check
